<mujoco model="Quadcopter">
  <compiler angle="degree" coordinate="local" inertiafromgeom="true" />
  <worldbody>
    <body name="chassis" pos="0 0 0">
      <geom density="50" pos="0 0 0" size="0.1 0.015" type="cylinder" />
      <joint name="root_joint" type="free" />
      <body name="rotor_arm0" pos="0.0724784 0.0724784 0" quat="0.92388 0 0 0.382683">
        <geom density="200" size="0.01" type="sphere" />
        <joint axis="0 1 0" limited="true" name="rotor_pitch0" pos="0 0 0" range="-30 30" type="hinge" />
        <body name="rotor0" pos="0.0425 0 0" quat="1 0 0 0">
          <geom density="1000" size="0.04 0.005" type="cylinder" />
          <joint axis="1 0 0" limited="true" name="rotor_roll0" pos="0 0 0" range="-30 30" type="hinge" />
        </body>
      </body>
      <body name="rotor_arm1" pos="-0.0724785 0.0724784 0" quat="0.382683 0 0 0.92388">
        <geom density="200" size="0.01" type="sphere" />
        <joint axis="0 1 0" limited="true" name="rotor_pitch1" pos="0 0 0" range="-30 30" type="hinge" />
        <body name="rotor1" pos="0.0425 0 0" quat="1 0 0 0">
          <geom density="1000" size="0.04 0.005" type="cylinder" />
          <joint axis="1 0 0" limited="true" name="rotor_roll1" pos="0 0 0" range="-30 30" type="hinge" />
        </body>
      </body>
      <body name="rotor_arm2" pos="-0.0724785 -0.0724784 0" quat="-0.382683 0 0 0.92388">
        <geom density="200" size="0.01" type="sphere" />
        <joint axis="0 1 0" limited="true" name="rotor_pitch2" pos="0 0 0" range="-30 30" type="hinge" />
        <body name="rotor2" pos="0.0425 0 0" quat="1 0 0 0">
          <geom density="1000" size="0.04 0.005" type="cylinder" />
          <joint axis="1 0 0" limited="true" name="rotor_roll2" pos="0 0 0" range="-30 30" type="hinge" />
        </body>
      </body>
      <body name="rotor_arm3" pos="0.0724784 -0.0724785 0" quat="-0.92388 0 0 0.382683">
        <geom density="200" size="0.01" type="sphere" />
        <joint axis="0 1 0" limited="true" name="rotor_pitch3" pos="0 0 0" range="-30 30" type="hinge" />
        <body name="rotor3" pos="0.0425 0 0" quat="1 0 0 0">
          <geom density="1000" size="0.04 0.005" type="cylinder" />
          <joint axis="1 0 0" limited="true" name="rotor_roll3" pos="0 0 0" range="-30 30" type="hinge" />
        </body>
      </body>
    </body>
  </worldbody>
</mujoco>
